Traceback (most recent call last):
  File "/Users/corrado/opt/anaconda3/envs/pymc_511/lib/python3.11/site-packages/jupyter_cache/executors/utils.py", line 58, in single_nb_execution
    executenb(
  File "/Users/corrado/opt/anaconda3/envs/pymc_511/lib/python3.11/site-packages/nbclient/client.py", line 1204, in execute
    return NotebookClient(nb=nb, resources=resources, km=km, **kwargs).execute()
           ^^^^^^^^^^^^^^^^^^^^^^^^^^^^^^^^^^^^^^^^^^^^^^^^^^^^^^^^^^^^^^^^^^^^^
  File "/Users/corrado/opt/anaconda3/envs/pymc_511/lib/python3.11/site-packages/nbclient/util.py", line 84, in wrapped
    return just_run(coro(*args, **kwargs))
           ^^^^^^^^^^^^^^^^^^^^^^^^^^^^^^^
  File "/Users/corrado/opt/anaconda3/envs/pymc_511/lib/python3.11/site-packages/nbclient/util.py", line 62, in just_run
    return loop.run_until_complete(coro)
           ^^^^^^^^^^^^^^^^^^^^^^^^^^^^^
  File "/Users/corrado/opt/anaconda3/envs/pymc_511/lib/python3.11/asyncio/base_events.py", line 650, in run_until_complete
    return future.result()
           ^^^^^^^^^^^^^^^
  File "/Users/corrado/opt/anaconda3/envs/pymc_511/lib/python3.11/contextlib.py", line 222, in __aexit__
    await self.gen.athrow(typ, value, traceback)
  File "/Users/corrado/opt/anaconda3/envs/pymc_511/lib/python3.11/site-packages/nbclient/client.py", line 608, in async_setup_kernel
    yield
  File "/Users/corrado/opt/anaconda3/envs/pymc_511/lib/python3.11/site-packages/nbclient/client.py", line 663, in async_execute
    await self.async_execute_cell(
  File "/Users/corrado/opt/anaconda3/envs/pymc_511/lib/python3.11/site-packages/nbclient/client.py", line 965, in async_execute_cell
    await self._check_raise_for_error(cell, cell_index, exec_reply)
  File "/Users/corrado/opt/anaconda3/envs/pymc_511/lib/python3.11/site-packages/nbclient/client.py", line 862, in _check_raise_for_error
    raise CellExecutionError.from_cell_and_msg(cell, exec_reply_content)
nbclient.exceptions.CellExecutionError: An error occurred while executing the following cell:
------------------
fit <- cfa(
  mod2,
  data = d,
  meanstructure = TRUE
)
------------------

Error in eval(mc, parent.frame()): object 'd' not found
Traceback:

1. cfa(mod2, data = d, meanstructure = TRUE)
2. eval(mc, parent.frame())
3. eval(mc, parent.frame())
4. lavaan::lavaan(model = mod2, data = d, meanstructure = TRUE, 
 .     model.type = "cfa", int.ov.free = TRUE, int.lv.free = FALSE, 
 .     auto.fix.first = TRUE, auto.fix.single = TRUE, auto.var = TRUE, 
 .     auto.cov.lv.x = TRUE, auto.cov.y = TRUE, auto.th = TRUE, 
 .     auto.delta = TRUE, auto.efa = TRUE)
ERROR: Error in eval(mc, parent.frame()): object 'd' not found


