Traceback (most recent call last):
  File "/Users/corrado/opt/anaconda3/envs/pymc_511/lib/python3.11/site-packages/jupyter_cache/executors/utils.py", line 58, in single_nb_execution
    executenb(
  File "/Users/corrado/opt/anaconda3/envs/pymc_511/lib/python3.11/site-packages/nbclient/client.py", line 1204, in execute
    return NotebookClient(nb=nb, resources=resources, km=km, **kwargs).execute()
           ^^^^^^^^^^^^^^^^^^^^^^^^^^^^^^^^^^^^^^^^^^^^^^^^^^^^^^^^^^^^^^^^^^^^^
  File "/Users/corrado/opt/anaconda3/envs/pymc_511/lib/python3.11/site-packages/nbclient/util.py", line 84, in wrapped
    return just_run(coro(*args, **kwargs))
           ^^^^^^^^^^^^^^^^^^^^^^^^^^^^^^^
  File "/Users/corrado/opt/anaconda3/envs/pymc_511/lib/python3.11/site-packages/nbclient/util.py", line 62, in just_run
    return loop.run_until_complete(coro)
           ^^^^^^^^^^^^^^^^^^^^^^^^^^^^^
  File "/Users/corrado/opt/anaconda3/envs/pymc_511/lib/python3.11/asyncio/base_events.py", line 650, in run_until_complete
    return future.result()
           ^^^^^^^^^^^^^^^
  File "/Users/corrado/opt/anaconda3/envs/pymc_511/lib/python3.11/contextlib.py", line 222, in __aexit__
    await self.gen.athrow(typ, value, traceback)
  File "/Users/corrado/opt/anaconda3/envs/pymc_511/lib/python3.11/site-packages/nbclient/client.py", line 608, in async_setup_kernel
    yield
  File "/Users/corrado/opt/anaconda3/envs/pymc_511/lib/python3.11/site-packages/nbclient/client.py", line 663, in async_execute
    await self.async_execute_cell(
  File "/Users/corrado/opt/anaconda3/envs/pymc_511/lib/python3.11/site-packages/nbclient/client.py", line 965, in async_execute_cell
    await self._check_raise_for_error(cell, cell_index, exec_reply)
  File "/Users/corrado/opt/anaconda3/envs/pymc_511/lib/python3.11/site-packages/nbclient/client.py", line 862, in _check_raise_for_error
    raise CellExecutionError.from_cell_and_msg(cell, exec_reply_content)
nbclient.exceptions.CellExecutionError: An error occurred while executing the following cell:
------------------
nice_lavaanPlot(lg_math_ticZERO_lavaan_fit, stand = TRUE, stars= FALSE)
------------------

Error in `$<-.data.frame`(`*tmp*`, "lhs", value = c("eta1", "eta1", "eta1", : replacement has 48 rows, data has 42
Traceback:

1. nice_lavaanPlot(lg_math_ticZERO_lavaan_fit, stand = TRUE, stars = FALSE)
2. lavaanPlot::lavaanPlot(model = model, node_options = node_options, 
 .     edge_options = edge_options, coefs = coefs, stand = stand, 
 .     covs = covs, stars = stars, graph_options = graph_options, 
 .     sig = sig, ...)
3. buildCall(name = name, model = model, labels = labels, ...)
4. paste(string, buildPaths(model, ...))
5. buildPaths(model, ...)
6. `$<-`(`*tmp*`, "lhs", value = c("eta1", "eta1", "eta1", "eta1", 
 . "eta1", "eta1", "eta1", "eta2", "eta2", "eta2", "eta2", "eta2", 
 . "eta2", "eta2", "eta1", "eta2", "eta1", "math2", "math3", "math4", 
 . "math5", "math6", "math7", "math8", "eta1", "eta2", "math2", 
 . "math3", "math4", "math5", "math6", "math7", "math8", "eta1", 
 . "eta1", "eta2", "eta2", "lb_wght", "anti_k1", "lb_wght", "lb_wght", 
 . "anti_k1", "p18", "p18", "p18", "p18", "p18", "p18"))
7. `$<-.data.frame`(`*tmp*`, "lhs", value = c("eta1", "eta1", "eta1", 
 . "eta1", "eta1", "eta1", "eta1", "eta2", "eta2", "eta2", "eta2", 
 . "eta2", "eta2", "eta2", "eta1", "eta2", "eta1", "math2", "math3", 
 . "math4", "math5", "math6", "math7", "math8", "eta1", "eta2", 
 . "math2", "math3", "math4", "math5", "math6", "math7", "math8", 
 . "eta1", "eta1", "eta2", "eta2", "lb_wght", "anti_k1", "lb_wght", 
 . "lb_wght", "anti_k1", "p18", "p18", "p18", "p18", "p18", "p18"
 . ))
8. stop(sprintf(ngettext(N, "replacement has %d row, data has %d", 
 .     "replacement has %d rows, data has %d"), N, nrows), domain = NA)
ERROR: Error in `$<-.data.frame`(`*tmp*`, "lhs", value = c("eta1", "eta1", "eta1", : replacement has 48 rows, data has 42


