Traceback (most recent call last):
  File "/Users/corrado/opt/anaconda3/envs/pymc_511/lib/python3.11/site-packages/jupyter_cache/executors/utils.py", line 58, in single_nb_execution
    executenb(
  File "/Users/corrado/opt/anaconda3/envs/pymc_511/lib/python3.11/site-packages/nbclient/client.py", line 1204, in execute
    return NotebookClient(nb=nb, resources=resources, km=km, **kwargs).execute()
           ^^^^^^^^^^^^^^^^^^^^^^^^^^^^^^^^^^^^^^^^^^^^^^^^^^^^^^^^^^^^^^^^^^^^^
  File "/Users/corrado/opt/anaconda3/envs/pymc_511/lib/python3.11/site-packages/nbclient/util.py", line 84, in wrapped
    return just_run(coro(*args, **kwargs))
           ^^^^^^^^^^^^^^^^^^^^^^^^^^^^^^^
  File "/Users/corrado/opt/anaconda3/envs/pymc_511/lib/python3.11/site-packages/nbclient/util.py", line 62, in just_run
    return loop.run_until_complete(coro)
           ^^^^^^^^^^^^^^^^^^^^^^^^^^^^^
  File "/Users/corrado/opt/anaconda3/envs/pymc_511/lib/python3.11/asyncio/base_events.py", line 650, in run_until_complete
    return future.result()
           ^^^^^^^^^^^^^^^
  File "/Users/corrado/opt/anaconda3/envs/pymc_511/lib/python3.11/contextlib.py", line 222, in __aexit__
    await self.gen.athrow(typ, value, traceback)
  File "/Users/corrado/opt/anaconda3/envs/pymc_511/lib/python3.11/site-packages/nbclient/client.py", line 608, in async_setup_kernel
    yield
  File "/Users/corrado/opt/anaconda3/envs/pymc_511/lib/python3.11/site-packages/nbclient/client.py", line 663, in async_execute
    await self.async_execute_cell(
  File "/Users/corrado/opt/anaconda3/envs/pymc_511/lib/python3.11/site-packages/nbclient/client.py", line 965, in async_execute_cell
    await self._check_raise_for_error(cell, cell_index, exec_reply)
  File "/Users/corrado/opt/anaconda3/envs/pymc_511/lib/python3.11/site-packages/nbclient/client.py", line 862, in _check_raise_for_error
    raise CellExecutionError.from_cell_and_msg(cell, exec_reply_content)
nbclient.exceptions.CellExecutionError: An error occurred while executing the following cell:
------------------
source("_common.R")
suppressPackageStartupMessages({
    library("tidyverse")
    library("lavaan")
    library("semPlot")
    library("psych")
    library("DT")
    library("kableExtra")
    library("lme4")
    library("emmeans")
})
set.seed(42)
------------------

Error in base_size/2: non-numeric argument to binary operator
Traceback:

1. source("_common.R")
2. withVisible(eval(ei, envir))
3. eval(ei, envir)
4. eval(ei, envir)
5. theme_set(bayesplot::theme_default(theme_minimal()))
6. bayesplot::theme_default(theme_minimal())
7. theme_bw(base_family = base_family, base_size = base_size)
8. theme_grey(base_size = base_size, base_family = base_family, 
 .     base_line_size = base_line_size, base_rect_size = base_rect_size) %+replace% 
 .     theme(panel.background = element_rect(fill = "white", colour = NA), 
 .         panel.border = element_rect(fill = NA, colour = "grey20"), 
 .         panel.grid = element_line(colour = "grey92"), panel.grid.minor = element_line(linewidth = rel(0.5)), 
 .         strip.background = element_rect(fill = "grey85", colour = "grey20"), 
 .         legend.key = element_rect(fill = "white", colour = NA), 
 .         complete = TRUE)
9. is.theme(e1)
10. theme_grey(base_size = base_size, base_family = base_family, 
  .     base_line_size = base_line_size, base_rect_size = base_rect_size)
ERROR: Error in base_size/2: non-numeric argument to binary operator


